Workbook

Sheet REMINDERS
A1: TREES | B1: STANDARD NUMBER OF TREES PER HECTARE | C1: PLANTING DISTANCE | E1: CROPS | F1: STANDARD NUMBER OF PLANTS PER HECTARE | G1: PLANTING DISTANCE
A2: COFFEE AND CACAO | B2: 1000 | C2: 3 X 3 | E2: AMPALAYA | F2: 3000 | G2: 1 X 3 / 0.5 X 3
A3: MANGO | B3: 53 TREES | E3: EGGPLANT | F3: 13000 | G3: 60 cm x 70 cm
A4: PAPAYA (RED LADY) | B4: 1000 | C4: 3 X 3 (2.5 X 2.5) | E4: SQUASH | F4: 3000 | G4: 1 X 3
A5: BANANA (SABA) | B5: 625 | E5: TOMATO | F5: 13000 | G5: 60 cm x 70 cm
A6: BANANA (LAKATAN) | B6: 1000 | C6: 3 X 3 | E6: OKRA | F6: 13000 | G6: 60 cm x 70 cm
A7: CALAMANSI | B7: 1000 | C7: 3 X 3 (1111) | E7: STRINGBEANS | F7: 10000 | G7: 0.5 X 1
A8: CASHEW | B8: 200 | C8: 7 X 7 | E8: HOT PEPPER | F8: 13000 | G8: 60 cm x 70 cm
A9: DRAGON FRUIT | B9: 1000 | C9: 3 X 3 | E9: PECHAY | F9: 200000 | G9: .25 cm X .25cm
A10: CHICO | B10: 100 | C10: 10 X 10 | E10: PATOLA | F10: 3000 | G10: 1 X 3 / 0.5 X 3
A11: JACKFRUIT | B11: 100 | C11: 10 X 10 | E11: UPO | F11: 3000 | G11: 1 X 3 / 0.5 X 3
A12: DURIAN | B12: 100 | C12: 10 X 10 | E12: CUCUMBER | F12: 10000 | G12: 0.5 X 1
A13: LANZONES | B13: 100 | C13: 10 X 10 | E13: LETTUCE | F13: 200000 | G13: .25 cm X .25cm
A14: RAMBUTAN | B14: 100 | C14: 10 X 10 | E14: WINGEDBEAN | F14: 10000 | G14: 0.5 X 1
A15: MONGOSTEEN | B15: 100 | C15: 10 X 10
A16: GUYABANO | B16: 100 | C16: 10 X 10
A17: AVOCADO | B17: 100 | C17: 10 X 10
A18: BATUAN | B18: 100 | C18: 10 X 10
A19: TAMARIND | B19: 100 | C19: 10 X 10
A20: BAMBOO | B20: 50 | C20: 20 X 20

Sheet Consolidatio Region VI
K1: HARVEST | L1: AREA HARVESTED | M1: AREA PLANTED | BA1: HARVEST | BB1: AREA HARVESTED | BC1: AREA PLANTED | EY1: HARVEST | EZ1: AREA HARVESTED | FA1: AREA PLANTED
D2: =NOW() -> 46092.506 | J2: JANUARY | K2: =SUM(P19+AE19+AT19) -> #REF! | L2: =SUM(O19+AD19+AS19) -> #REF! | M2: =SUM(N19+AC19+AR19) -> #REF! | AY2: COFFEE | AZ2: JANUARY | BA2: =SUM(BI19+BX19+CM19) -> #REF! | BB2: =SUM(BH19+BW19+CL19) -> #REF! | BC2: =SUM(BG19+BV19+CK19) -> #REF! | EX2: JANUARY | EY2: =SUM(FJ19+FY19+GN19) -> #REF! | EZ2: =SUM(FI19+FX19+GM19) -> #REF! | FA2: =SUM(FH19+FW19+GL19) -> #REF! | FB2: BANANA
J3: FEBRUARY | K3: =SUM(P20+AE20+AT20) -> #REF! | L3: =SUM(O20+AD20+AS20) -> #REF! | M3: =SUM(N20+AC20+AR20) -> #REF! | AZ3: FEBRUARY | BA3: =SUM(BI20+BX20+CM20) -> #REF! | BB3: =SUM(BH20+BW20+CL20) -> #REF! | BC3: =SUM(BG20+BV20+CK20) -> #REF! | EX3: FEBRUARY | EY3: =SUM(FJ20+FY20+GN20) -> #REF! | EZ3: =SUM(FI20+FX20+GM20) -> #REF! | FA3: =SUM(FH20+FW20+GL20) -> #REF!
I4: CACAO | J4: MARCH | K4: =SUM(P21+AE21+AT21) -> #REF! | L4: =SUM(O21+AD21+AS21) -> #REF! | M4: =SUM(N21+AC21+AR21) -> #REF! | AZ4: MARCH | BA4: =SUM(BI21+BX21+CM21) -> #REF! | BB4: =SUM(BH21+BW21+CL21) -> #REF! | BC4: =SUM(BG21+BV21+CK21) -> #REF! | EX4: MARCH | EY4: =SUM(FJ21+FY21+GN21) -> #REF! | EZ4: =SUM(FI21+FX21+GM21) -> #REF! | FA4: =SUM(FH21+FW21+GL21) -> #REF!
J5: APRIL | K5: =SUM(P22+AE22+AT22) -> #REF! | L5: =SUM(O22+AD22+AS22) -> #REF! | M5: =SUM(N22+AC22+AR22) -> #REF! | AZ5: APRIL | BA5: =SUM(BI22+BX22+CM22) -> #REF! | BB5: =SUM(BH22+BW22+CL22) -> #REF! | BC5: =SUM(BG22+BV22+CK22) -> #REF! | EX5: APRIL | EY5: =SUM(FJ22+FY22+GN22) -> #REF! | EZ5: =SUM(FI22+FX22+GM22) -> #REF! | FA5: =SUM(FH22+FW22+GL22) -> #REF!
J6: MAY | K6: =SUM(P23+AE23+AT23) -> #REF! | L6: =SUM(O23+AD23+AS23) -> #REF! | M6: =SUM(N23+AC23+AR23) -> #REF! | AZ6: MAY | BA6: =SUM(BI23+BX23+CM23) -> #REF! | BB6: =SUM(BH23+BW23+CL23) -> #REF! | BC6: =SUM(BG23+BV23+CK23) -> #REF! | EX6: MAY | EY6: =SUM(FJ23+FY23+GN23) -> #REF! | EZ6: =SUM(FI23+FX23+GM23) -> #REF! | FA6: =SUM(FH23+FW23+GL23) -> #REF!
J7: JUNE | K7: =SUM(P24+AE24+AT24) -> #REF! | L7: =SUM(O24+AD24+AS24) -> #REF! | M7: =SUM(N24+AC24+AR24) -> #REF! | AZ7: JUNE | BA7: =SUM(BI24+BX24+CM24) -> #REF! | BB7: =SUM(BH24+BW24+CL24) -> #REF! | BC7: =SUM(BG24+BV24+CK24) -> #REF! | EX7: JUNE | EY7: =SUM(FJ24+FY24+GN24) -> #REF! | EZ7: =SUM(FI24+FX24+GM24) -> #REF! | FA7: =SUM(FH24+FW24+GL24) -> #REF!
J8: JULY | K8: =SUM(P25+AE25+AT25) -> #REF! | L8: =SUM(O25+AD25+AS25) -> #REF! | M8: =SUM(N25+AC25+AR25) -> #REF! | AZ8: JULY | BA8: =SUM(BI25+BX25+CM25) -> #REF! | BB8: =SUM(BH25+BW25+CL25) -> #REF! | BC8: =SUM(BG25+BV25+CK25) -> #REF! | EX8: JULY | EY8: =SUM(FJ25+FY25+GN25) -> #REF! | EZ8: =SUM(FI25+FX25+GM25) -> #REF! | FA8: =SUM(FH25+FW25+GL25) -> #REF!
J9: AUGUST | K9: =SUM(P26+AE26+AT26) -> #REF! | L9: =SUM(O26+AD26+AS26) -> #REF! | M9: =SUM(N26+AC26+AR26) -> #REF! | AZ9: AUGUST | BA9: =SUM(BI26+BX26+CM26) -> #REF! | BB9: =SUM(BH26+BW26+CL26) -> #REF! | BC9: =SUM(BG26+BV26+CK26) -> #REF! | EX9: AUGUST | EY9: =SUM(FJ26+FY26+GN26) -> #REF! | EZ9: =SUM(FI26+FX26+GM26) -> #REF! | FA9: =SUM(FH26+FW26+GL26) -> #REF!
J10: SEPTEMBER | K10: =SUM(P27+AE27+AT27) -> #REF! | L10: =SUM(O27+AD27+AS27) -> #REF! | M10: =SUM(N27+AC27+AR27) -> #REF! | AZ10: SEPTEMBER | BA10: =SUM(BI27+BX27+CM27) -> #REF! | BB10: =SUM(BH27+BW27+CL27) -> #REF! | BC10: =SUM(BG27+BV27+CK27) -> #REF! | EX10: SEPTEMBER | EY10: =SUM(FJ27+FY27+GN27) -> #REF! | EZ10: =SUM(FI27+FX27+GM27) -> #REF! | FA10: =SUM(FH27+FW27+GL27) -> #REF!
J11: OCTOBER | K11: =SUM(P28+AE28+AT28) -> #REF! | L11: =SUM(O28+AD28+AS28) -> #REF! | M11: =SUM(N28+AC28+AR28) -> #REF! | AZ11: OCTOBER | BA11: =SUM(BI28+BX28+CM28) -> #REF! | BB11: =SUM(BH28+BW28+CL28) -> #REF! | BC11: =SUM(BG28+BV28+CK28) -> #REF! | EX11: OCTOBER | EY11: =SUM(FJ28+FY28+GN28) -> #REF! | EZ11: =SUM(FI28+FX28+GM28) -> #REF! | FA11: =SUM(FH28+FW28+GL28) -> #REF!
J12: NOVEMBER | K12: =SUM(P29+AE29+AT29) -> #REF! | L12: =SUM(O29+AD29+AS29) -> #REF! | M12: =SUM(N29+AC29+AR29) -> #REF! | AZ12: NOVEMBER | BA12: =SUM(BI29+BX29+CM29) -> #REF! | BB12: =SUM(BH29+BW29+CL29) -> #REF! | BC12: =SUM(BG29+BV29+CK29) -> #REF! | EX12: NOVEMBER | EY12: =SUM(FJ29+FY29+GN29) -> #REF! | EZ12: =SUM(FI29+FX29+GM29) -> #REF! | FA12: =SUM(FH29+FW29+GL29) -> #REF!
J13: DECEMBER | K13: =SUM(P30+AE30+AT30) -> #REF! | L13: =SUM(O30+AD30+AS30) -> #REF! | M13: =SUM(N30+AC30+AR30) -> #REF! | AZ13: DECEMBER | BA13: =SUM(BI30+BX30+CM30) -> #REF! | BB13: =SUM(BH30+BW30+CL30) -> #REF! | BC13: =SUM(BG30+BV30+CK30) -> #REF! | EX13: DECEMBER | EY13: =SUM(FJ30+FY30+GN30) -> #REF! | EZ13: =SUM(FI30+FX30+GM30) -> #REF! | FA13: =SUM(FH30+FW30+GL30) -> #REF!
B14: PROVINCE / MUNICIPALITY | C14: MONTH | D14: I N D U S T R I A L C R O P S I N D U S T R I A L C R O P S I N D U S T R I A L C R O P S | Z14: I N D U S T R I A L C R O P S I N D U S T R I A L C R O P S I N D U S T R I A L C R O P S | AU14: I N D U S T R I A L C R O P S I N D U S T R I A L C R O P S I N D U S T R I A L C R O P S | BI14: I N D U S T R I A L C R O P S I N D U S T R I A L C R O P S I N D U S T R I A L C R O P S | CF14: I N D U S T R I A L C R O P S I N D U S T R I A L C R O P S | CZ14: I N D U S T R I A L C R O P S I N D U S T R I A L C R O P S I N D U S T R I A L C R O P S | DT14: P L A N T A T I O N C R O P S P L A N T A T I O N C R O P S P L A N T A T I O N | ER14: P L A N T A T I O N C R O P S P L A N T A T I O N C R O P S P L A N T A T I O N | FS14: P L A N T A T I O N C R O P S P L A N T A T I O N C R O P S P L A N T A T I O N | GT14: P L A N T A T I O N C R O P S P L A N T A T I O N C R O P S P L A N T A T I O N | HS14: P L A N T A T I O N C R O P S P L A N T A T I O N C R O P S P L A N T A T I O N | IS14: P L A N T A T I O N C R O P S P L A N T A T I O N C R O P S P L A N T A T I O N | JS14: P L A N T A T I O N C R O P S | KC14: F R U I T T R E E S F R U I T T R E E S F R U I T T R E E S F R U I T T R E E S | LD14: F R U I T T R E E S F R U I T T R E E S F R U I T T R E E S F R U I T T R E E S | MF14: F R U I T T R E E S F R U I T T R E E S F R U I T T R E E S F R U I T T R E E S | NH14: F R U I T T R E E S F R U I T T R E E S F R U I T T R E E S F R U I T T R E E S | OK14: F R U I T T R E E S F R U I T T R E E S F R U I T T R E E S F R U I T T R E E S | PO14: F R U I T T R E E S F R U I T T R E E S F R U I T T R E E S | QL14: O T H E R S O T H E R S O T H E R S O T H E R S O T H E R S O T H E R S O T H E R S | RR14: O T H E R S O T H E R S O T H E R S O T H E R S O T H E R S O T H E R S O T H E R S | SV14: O T H E R S O T H E R S O T H E R S O T H E R S O T H E R S O T H E R S O T H E R S | TZ14: O T H E R S O T H E R S O T H E R S O T H E R S O T H E R S O T H E R S O T H E R S | VB14: O T H E R S O T H E R S O T H E R S O T H E R S O T H E R S O T H E R S O T H E R S
D15: CACAO - CRIOLLO | S15: CACAO FORASTERO | AH15: CACAO - TRINITARIO | AW15: COFFEE - ARABICA | BL15: COFFEE - LIBERICA | CA15: COFFEE - ROBUSTA | CP15: CASHEW | DE15: DURIAN | DT15: MANGO - CARABAO | EI15: MANGO - INDIAN | EX15: BANANA - LAKATAN | FM15: BANANA - SABA | GB15: BANANA - LATUNDAN | GQ15: PINEAPPLE | HF15: PAPAYA | HU15: CALAMANSI | IJ15: DRAGON FRUIT | IY15: WATERMELON | JN15: SUGARCANE | KC15: LANZONES | KR15: RAMBUTAN | LG15: MANGOSTEEN | LV15: GUYABANO | MK15: JACKFRUIT | MZ15: AVOCADO | NO15: MARANG | OD15: POMELO | OS15: GUAVA | PH15: STAR APPLE | PW15: SANTOL | QL15: CHICO | RA15: TAMARIND | RP15: BAMBOO | SE15: BATUAN | ST15: COCONUT | TI15: MUSK MELON | TX15: COTTON | UM15: LEMON | VB15: ABACA | VQ15: KAMATSILE
D16: NUMBER OF FARMERS | F16: TOTAL | G16: NUMBER OF TREES | J16: TOTAL | K16: NEWLY PLANTED (HA) | L16: EXISTING AREA PLANTED (HA) | M16: MORTALITY RATE (HA) | N16: TOTAL AREA PLANTED (HA) | O16: AREA HARVESTED (HA) | P16: VOLUME OF PRODUCTION (MT) | Q16: REMARKS | S16: NUMBER OF FARMERS | U16: TOTAL | V16: NUMBER OF TREES | Y16: TOTAL | Z16: NEWLY PLANTED (HA) | AA16: EXISTING AREA PLANTED (HA) | AB16: MORTALITY RATE (HA) | AC16: TOTAL AREA PLANTED (HA) | AD16: AREA HARVESTED (HA) | AE16: VOLUME OF PRODUCTION (MT) | AF16: REMARKS | AH16: NUMBER OF FARMERS | AJ16: TOTAL | AK16: NUMBER OF TREES | AN16: TOTAL | AO16: NEWLY PLANTED (HA) | AP16: EXISTING AREA PLANTED (HA) | AQ16: MORTALITY RATE (HA) | AR16: TOTAL AREA PLANTED (HA) | AS16: AREA HARVESTED (HA) | AT16: VOLUME OF PRODUCTION (MT) | AU16: REMARKS | AW16: NUMBER OF FARMERS | AY16: TOTAL | AZ16: NUMBER OF TREES | BC16: TOTAL | BD16: NEWLY PLANTED (HA) | BE16: EXISTING AREA PLANTED (HA) | BF16: MORTALITY RATE (HA) | BG16: TOTAL AREA PLANTED (HA) | BH16: AREA HARVESTED (HA) | BI16: VOLUME OF PRODUCTION (MT) | BJ16: REMARKS | BL16: NUMBER OF FARMERS | BN16: TOTAL | BO16: NUMBER OF TREES | BR16: TOTAL | BS16: NEWLY PLANTED (HA) | BT16: EXISTING AREA PLANTED (HA) | BU16: MORTALITY RATE (HA) | BV16: TOTAL AREA PLANTED (HA) | BW16: AREA HARVESTED (HA) | BX16: VOLUME OF PRODUCTION (MT) | BY16: REMARKS | CA16: NUMBER OF FARMERS | CC16: TOTAL | CD16: NUMBER OF TREES | CG16: TOTAL | CH16: NEWLY PLANTED (HA) | CI16: EXISTING AREA PLANTED (HA) | CJ16: MORTALITY RATE (HA) | CK16: TOTAL AREA PLANTED (HA) | CL16: AREA HARVESTED (HA) | CM16: VOLUME OF PRODUCTION (MT) | CN16: REMARKS | CP16: NUMBER OF FARMERS | CR16: TOTAL | CS16: NUMBER OF TREES | CV16: TOTAL | CW16: NEWLY PLANTED (HA) | CX16: EXISTING AREA PLANTED (HA) | CY16: MORTALITY RATE (HA) | CZ16: TOTAL AREA PLANTED (HA) | DA16: AREA HARVESTED (HA) | DB16: VOLUME OF PRODUCTION (MT) | DC16: REMARKS | DE16: NUMBER OF FARMERS | DG16: TOTAL | DH16: NUMBER OF TREES | DK16: TOTAL | DL16: NEWLY PLANTED (HA) | DM16: EXISTING AREA PLANTED (HA) | DN16: MORTALITY RATE (HA) | DO16: TOTAL AREA PLANTED (HA) | DP16: AREA HARVESTED (HA) | DQ16: VOLUME OF PRODUCTION (MT) | DR16: REMARKS | DT16: NUMBER OF FARMERS | DV16: TOTAL | DW16: NUMBER OF TREES | DZ16: TOTAL | EA16: NEWLY PLANTED (HA) | EB16: EXISTING AREA PLANTED (HA) | EC16: MORTALITY RATE (HA) | ED16: TOTAL AREA PLANTED (HA) | EE16: AREA HARVESTED (HA) | EF16: VOLUME OF PRODUCTION (MT) | EG16: REMARKS | EI16: NUMBER OF FARMERS | EK16: TOTAL | EL16: NUMBER OF TREES | EO16: TOTAL | EP16: NEWLY PLANTED (HA) | EQ16: EXISTING AREA PLANTED (HA) | ER16: MORTALITY RATE (HA) | ES16: TOTAL AREA PLANTED (HA) | ET16: AREA HARVESTED (HA) | EU16: VOLUME OF PRODUCTION (MT) | EV16: REMARKS | EX16: NUMBER OF FARMERS | EZ16: TOTAL | FA16: NUMBER OF TREES | FD16: TOTAL | FE16: NEWLY PLANTED (HA) | FF16: EXISTING AREA PLANTED (HA) | FG16: MORTALITY RATE (HA) | FH16: TOTAL AREA PLANTED (HA) | FI16: AREA HARVESTED (HA) | FJ16: VOLUME OF PRODUCTION (MT) | FK16: REMARKS | FM16: NUMBER OF FARMERS | FO16: TOTAL | FP16: NUMBER OF TREES | FS16: TOTAL | FT16: NEWLY PLANTED (HA) | FU16: EXISTING AREA PLANTED (HA) | FV16: MORTALITY RATE (HA) | FW16: TOTAL AREA PLANTED (HA) | FX16: AREA HARVESTED (HA) | FY16: VOLUME OF PRODUCTION (MT) | FZ16: REMARKS | GB16: NUMBER OF FARMERS | GD16: TOTAL | GE16: NUMBER OF TREES | GH16: TOTAL | GI16: NEWLY PLANTED (HA) | GJ16: EXISTING AREA PLANTED (HA) | GK16: MORTALITY RATE (HA) | GL16: TOTAL AREA PLANTED (HA) | GM16: AREA HARVESTED (HA) | GN16: VOLUME OF PRODUCTION (MT) | GO16: REMARKS | GQ16: NUMBER OF FARMERS | GS16: TOTAL | GT16: NUMBER OF TREES | GW16: TOTAL | GX16: NEWLY PLANTED (HA) | GY16: EXISTING AREA PLANTED (HA) | GZ16: MORTALITY RATE (HA) | HA16: TOTAL AREA PLANTED (HA) | HB16: AREA HARVESTED (HA) | HC16: VOLUME OF PRODUCTION (MT) | HD16: REMARKS | HF16: NUMBER OF FARMERS | HH16: TOTAL | HI16: NUMBER OF TREES | HL16: TOTAL | HM16: NEWLY PLANTED (HA) | HN16: EXISTING AREA PLANTED (HA) | HO16: MORTALITY RATE (HA) | HP16: TOTAL AREA PLANTED (HA) | HQ16: AREA HARVESTED (HA) | HR16: VOLUME OF PRODUCTION (MT) | HS16: REMARKS | HU16: NUMBER OF FARMERS | HW16: TOTAL | HX16: NUMBER OF TREES | IA16: TOTAL | IB16: NEWLY PLANTED (HA) | IC16: EXISTING AREA PLANTED (HA) | ID16: MORTALITY RATE (HA) | IE16: TOTAL AREA PLANTED (HA) | IF16: AREA HARVESTED (HA) | IG16: VOLUME OF PRODUCTION (MT) | IH16: REMARKS | IJ16: NUMBER OF FARMERS | IL16: TOTAL | IM16: NUMBER OF TREES | IP16: TOTAL | IQ16: NEWLY PLANTED (HA) | IR16: EXISTING AREA PLANTED (HA) | IS16: MORTALITY RATE (HA) | IT16: TOTAL AREA PLANTED (HA) | IU16: AREA HARVESTED (HA) | IV16: VOLUME OF PRODUCTION (MT) | IW16: REMARKS | IY16: NUMBER OF FARMERS | JA16: TOTAL | JB16: NUMBER OF TREES | JE16: TOTAL | JF16: NEWLY PLANTED (HA) | JG16: EXISTING AREA PLANTED (HA) | JH16: MORTALITY RATE (HA) | JI16: TOTAL AREA PLANTED (HA) | JJ16: AREA HARVESTED (HA) | JK16: VOLUME OF PRODUCTION (MT) | JL16: REMARKS | JN16: NUMBER OF FARMERS | JP16: TOTAL | JQ16: NUMBER OF TREES | JT16: TOTAL | JU16: NEWLY PLANTED (HA) | JV16: EXISTING AREA PLANTED (HA) | JW16: MORTALITY RATE (HA) | JX16: TOTAL AREA PLANTED (HA) | JY16: AREA HARVESTED (HA) | JZ16: VOLUME OF PRODUCTION (MT) | KA16: REMARKS | KC16: NUMBER OF FARMERS | KE16: TOTAL | KF16: NUMBER OF TREES | KI16: TOTAL | KJ16: NEWLY PLANTED (HA) | KK16: EXISTING AREA PLANTED (HA) | KL16: MORTALITY RATE (HA) | KM16: TOTAL AREA PLANTED (HA) | KN16: AREA HARVESTED (HA) | KO16: VOLUME OF PRODUCTION (MT) | KP16: REMARKS | KR16: NUMBER OF FARMERS | KT16: TOTAL | KU16: NUMBER OF TREES | KX16: TOTAL | KY16: NEWLY PLANTED (HA) | KZ16: EXISTING AREA PLANTED (HA) | LA16: MORTALITY RATE (HA) | LB16: TOTAL AREA PLANTED (HA) | LC16: AREA HARVESTED (HA) | LD16: VOLUME OF PRODUCTION (MT) | LE16: REMARKS | LG16: NUMBER OF FARMERS | LI16: TOTAL | LJ16: NUMBER OF TREES | LM16: TOTAL | LN16: NEWLY PLANTED (HA) | LO16: EXISTING AREA PLANTED (HA) | LP16: MORTALITY RATE (HA) | LQ16: TOTAL AREA PLANTED (HA) | LR16: AREA HARVESTED (HA) | LS16: VOLUME OF PRODUCTION (MT) | LT16: REMARKS | LV16: NUMBER OF FARMERS | LX16: TOTAL | LY16: NUMBER OF TREES | MB16: TOTAL | MC16: NEWLY PLANTED (HA) | MD16: EXISTING AREA PLANTED (HA) | ME16: MORTALITY RATE (HA) | MF16: TOTAL AREA PLANTED (HA) | MG16: AREA HARVESTED (HA) | MH16: VOLUME OF PRODUCTION (MT) | MI16: REMARKS | MK16: NUMBER OF FARMERS | MM16: TOTAL | MN16: NUMBER OF TREES | MQ16: TOTAL | MR16: NEWLY PLANTED (HA) | MS16: EXISTING AREA PLANTED (HA) | MT16: MORTALITY RATE (HA) | MU16: TOTAL AREA PLANTED (HA) | MV16: AREA HARVESTED (HA) | MW16: VOLUME OF PRODUCTION (MT) | MX16: REMARKS | MZ16: NUMBER OF FARMERS | NB16: TOTAL | NC16: NUMBER OF TREES | NF16: TOTAL | NG16: NEWLY PLANTED (HA) | NH16: EXISTING AREA PLANTED (HA) | NI16: MORTALITY RATE (HA) | NJ16: TOTAL AREA PLANTED (HA) | NK16: AREA HARVESTED (HA) | NL16: VOLUME OF PRODUCTION (MT) | NM16: REMARKS | NO16: NUMBER OF FARMERS | NQ16: TOTAL | NR16: NUMBER OF TREES | NU16: TOTAL | NV16: NEWLY PLANTED (HA) | NW16: EXISTING AREA PLANTED (HA) | NX16: MORTALITY RATE (HA) | NY16: TOTAL AREA PLANTED (HA) | NZ16: AREA HARVESTED (HA) | OA16: VOLUME OF PRODUCTION (MT) | OB16: REMARKS | OD16: NUMBER OF FARMERS | OF16: TOTAL | OG16: NUMBER OF TREES | OJ16: TOTAL | OK16: NEWLY PLANTED (HA) | OL16: EXISTING AREA PLANTED (HA) | OM16: MORTALITY RATE (HA) | ON16: TOTAL AREA PLANTED (HA) | OO16: AREA HARVESTED (HA) | OP16: VOLUME OF PRODUCTION (MT) | OQ16: REMARKS | OS16: NUMBER OF FARMERS | OU16: TOTAL | OV16: NUMBER OF TREES | OY16: TOTAL | OZ16: NEWLY PLANTED (HA) | PA16: EXISTING AREA PLANTED (HA) | PB16: MORTALITY RATE (HA) | PC16: TOTAL AREA PLANTED (HA) | PD16: AREA HARVESTED (HA) | PE16: VOLUME OF PRODUCTION (MT) | PF16: REMARKS | PH16: NUMBER OF FARMERS | PJ16: TOTAL | PK16: NUMBER OF TREES | PN16: TOTAL | PO16: NEWLY PLANTED (HA) | PP16: EXISTING AREA PLANTED (HA) | PQ16: MORTALITY RATE (HA) | PR16: TOTAL AREA PLANTED (HA) | PS16: AREA HARVESTED (HA) | PT16: VOLUME OF PRODUCTION (MT) | PU16: REMARKS | PW16: NUMBER OF FARMERS | PY16: TOTAL | PZ16: NUMBER OF TREES | QC16: TOTAL | QD16: NEWLY PLANTED (HA) | QE16: EXISTING AREA PLANTED (HA) | QF16: MORTALITY RATE (HA) | QG16: TOTAL AREA PLANTED (HA) | QH16: AREA HARVESTED (HA) | QI16: VOLUME OF PRODUCTION (MT) | QJ16: REMARKS | QL16: NUMBER OF FARMERS | QN16: TOTAL | QO16: NUMBER OF TREES | QR16: TOTAL | QS16: NEWLY PLANTED (HA) | QT16: EXISTING AREA PLANTED (HA) | QU16: MORTALITY RATE (HA) | QV16: TOTAL AREA PLANTED (HA) | QW16: AREA HARVESTED (HA) | QX16: VOLUME OF PRODUCTION (MT) | QY16: REMARKS | RA16: NUMBER OF FARMERS | RC16: TOTAL | RD16: NUMBER OF TREES | RG16: TOTAL | RH16: NEWLY PLANTED (HA) | RI16: EXISTING AREA PLANTED (HA) | RJ16: MORTALITY RATE (HA) | RK16: TOTAL AREA PLANTED (HA) | RL16: AREA HARVESTED (HA) | RM16: VOLUME OF PRODUCTION (MT) | RN16: REMARKS | RP16: NUMBER OF FARMERS | RR16: TOTAL | RS16: NUMBER OF TREES | RV16: TOTAL | RW16: NEWLY PLANTED (HA) | RX16: EXISTING AREA PLANTED (HA) | RY16: MORTALITY RATE (HA) | RZ16: TOTAL AREA PLANTED (HA) | SA16: AREA HARVESTED (HA) | SB16: VOLUME OF PRODUCTION (MT) | SC16: REMARKS | SE16: NUMBER OF FARMERS | SG16: TOTAL | SH16: NUMBER OF TREES | SK16: TOTAL | SL16: NEWLY PLANTED (HA) | SM16: EXISTING AREA PLANTED (HA) | SN16: MORTALITY RATE (HA) | SO16: TOTAL AREA PLANTED (HA) | SP16: AREA HARVESTED (HA) | SQ16: VOLUME OF PRODUCTION (MT) | SR16: REMARKS | ST16: NUMBER OF FARMERS | SV16: TOTAL | SW16: NUMBER OF TREES | SZ16: TOTAL | TA16: NEWLY PLANTED (HA) | TB16: EXISTING AREA PLANTED (HA) | TC16: MORTALITY RATE (HA) | TD16: TOTAL AREA PLANTED (HA) | TE16: AREA HARVESTED (HA) | TF16: VOLUME OF PRODUCTION (MT) | TG16: REMARKS | TI16: NUMBER OF FARMERS | TK16: TOTAL | TL16: NUMBER OF TREES | TO16: TOTAL | TP16: NEWLY PLANTED (HA) | TQ16: EXISTING AREA PLANTED (HA) | TR16: MORTALITY RATE (HA) | TS16: TOTAL AREA PLANTED (HA) | TT16: AREA HARVESTED (HA) | TU16: VOLUME OF PRODUCTION (MT) | TV16: REMARKS | TX16: NUMBER OF FARMERS | TZ16: TOTAL | UA16: NUMBER OF TREES | UD16: TOTAL | UE16: NEWLY PLANTED (HA) | UF16: EXISTING AREA PLANTED (HA) | UG16: MORTALITY RATE (HA) | UH16: TOTAL AREA PLANTED (HA) | UI16: AREA HARVESTED (HA) | UJ16: VOLUME OF PRODUCTION (MT) | UK16: REMARKS | UM16: NUMBER OF FARMERS | UO16: TOTAL | UP16: NUMBER OF TREES | US16: TOTAL | UT16: NEWLY PLANTED (HA) | UU16: EXISTING AREA PLANTED (HA) | UV16: MORTALITY RATE (HA) | UW16: TOTAL AREA PLANTED (HA) | UX16: AREA HARVESTED (HA) | UY16: VOLUME OF PRODUCTION (MT) | UZ16: REMARKS | VB16: NUMBER OF FARMERS | VD16: TOTAL | VE16: NUMBER OF TREES | VH16: TOTAL | VI16: NEWLY PLANTED (HA) | VJ16: EXISTING AREA PLANTED (HA) | VK16: MORTALITY RATE (HA) | VL16: TOTAL AREA PLANTED (HA) | VM16: AREA HARVESTED (HA) | VN16: VOLUME OF PRODUCTION (MT) | VO16: REMARKS | VQ16: NUMBER OF FARMERS | VS16: TOTAL | VT16: NUMBER OF TREES | VW16: TOTAL | VX16: NEWLY PLANTED (HA) | VY16: EXISTING AREA PLANTED (HA) | VZ16: MORTALITY RATE (HA) | WA16: TOTAL AREA PLANTED (HA) | WB16: AREA HARVESTED (HA) | WC16: VOLUME OF PRODUCTION (MT) | WD16: REMARKS
D17: MALE | E17: FEMALE | G17: BEARING | H17: NON-BEARING | I17: MORTALITY | S17: MALE | T17: FEMALE | V17: BEARING | W17: NON-BEARING | X17: MORTALITY | AH17: MALE | AI17: FEMALE | AK17: BEARING | AL17: NON-BEARING | AM17: MORTALITY | AW17: MALE | AX17: FEMALE | AZ17: BEARING | BA17: NON-BEARING | BB17: MORTALITY | BL17: MALE | BM17: FEMALE | BO17: BEARING | BP17: NON-BEARING | BQ17: MORTALITY | CA17: MALE | CB17: FEMALE | CD17: BEARING | CE17: NON-BEARING | CF17: MORTALITY | CP17: MALE | CQ17: FEMALE | CS17: BEARING | CT17: NON-BEARING | CU17: MORTALITY | DE17: MALE | DF17: FEMALE | DH17: BEARING | DI17: NON-BEARING | DJ17: MORTALITY | DT17: MALE | DU17: FEMALE | DW17: BEARING | DX17: NON-BEARING | DY17: MORTALITY | EI17: MALE | EJ17: FEMALE | EL17: BEARING | EM17: NON-BEARING | EN17: MORTALITY | EX17: MALE | EY17: FEMALE | FA17: BEARING | FB17: NON-BEARING | FC17: MORTALITY | FM17: MALE | FN17: FEMALE | FP17: BEARING | FQ17: NON-BEARING | FR17: MORTALITY | GB17: MALE | GC17: FEMALE | GE17: BEARING | GF17: NON-BEARING | GG17: MORTALITY | GQ17: MALE | GR17: FEMALE | GT17: BEARING | GU17: NON-BEARING | GV17: MORTALITY | HF17: MALE | HG17: FEMALE | HI17: BEARING | HJ17: NON-BEARING | HK17: MORTALITY | HU17: MALE | HV17: FEMALE | HX17: BEARING | HY17: NON-BEARING | HZ17: MORTALITY | IJ17: MALE | IK17: FEMALE | IM17: BEARING | IN17: NON-BEARING | IO17: MORTALITY | IY17: MALE | IZ17: FEMALE | JB17: BEARING | JC17: NON-BEARING | JD17: MORTALITY | JN17: MALE | JO17: FEMALE | JQ17: BEARING | JR17: NON-BEARING | JS17: MORTALITY | KC17: MALE | KD17: FEMALE | KF17: BEARING | KG17: NON-BEARING | KH17: MORTALITY | KR17: MALE | KS17: FEMALE | KU17: BEARING | KV17: NON-BEARING | KW17: MORTALITY | LG17: MALE | LH17: FEMALE | LJ17: BEARING | LK17: NON-BEARING | LL17: MORTALITY | LV17: MALE | LW17: FEMALE | LY17: BEARING | LZ17: NON-BEARING | MA17: MORTALITY | MK17: MALE | ML17: FEMALE | MN17: BEARING | MO17: NON-BEARING | MP17: MORTALITY | MZ17: MALE | NA17: FEMALE | NC17: BEARING | ND17: NON-BEARING | NE17: MORTALITY | NO17: MALE | NP17: FEMALE | NR17: BEARING | NS17: NON-BEARING | NT17: MORTALITY | OD17: MALE | OE17: FEMALE | OG17: BEARING | OH17: NON-BEARING | OI17: MORTALITY | OS17: MALE | OT17: FEMALE | OV17: BEARING | OW17: NON-BEARING | OX17: MORTALITY | PH17: MALE | PI17: FEMALE | PK17: BEARING | PL17: NON-BEARING | PM17: MORTALITY | PW17: MALE | PX17: FEMALE | PZ17: BEARING | QA17: NON-BEARING | QB17: MORTALITY | QL17: MALE | QM17: FEMALE | QO17: BEARING | QP17: NON-BEARING | QQ17: MORTALITY | RA17: MALE | RB17: FEMALE | RD17: BEARING | RE17: NON-BEARING | RF17: MORTALITY | RP17: MALE | RQ17: FEMALE | RS17: BEARING | RT17: NON-BEARING | RU17: MORTALITY | SE17: MALE | SF17: FEMALE | SH17: BEARING | SI17: NON-BEARING | SJ17: MORTALITY | ST17: MALE | SU17: FEMALE | SW17: BEARING | SX17: NON-BEARING | SY17: MORTALITY | TI17: MALE | TJ17: FEMALE | TL17: BEARING | TM17: NON-BEARING | TN17: MORTALITY | TX17: MALE | TY17: FEMALE | UA17: BEARING | UB17: NON-BEARING | UC17: MORTALITY | UM17: MALE | UN17: FEMALE | UP17: BEARING | UQ17: NON-BEARING | UR17: MORTALITY | VB17: MALE | VC17: FEMALE | VE17: BEARING | VF17: NON-BEARING | VG17: MORTALITY | VQ17: MALE | VR17: FEMALE | VT17: BEARING | VU17: NON-BEARING | VV17: MORTALITY
D18: =SUBTOTAL(9,D19:D30) -> #REF! | E18: =SUBTOTAL(9,E19:E30) -> #REF! | F18: =SUBTOTAL(9,F19:F30) -> #REF! | G18: =SUBTOTAL(9,G19:G30) -> #REF! | H18: =SUBTOTAL(9,H19:H30) -> #REF! | I18: =SUBTOTAL(9,I19:I30) -> #REF! | J18: =SUM(G18:H18)-I18 -> #REF! | K18: =SUBTOTAL(9,K19:K30) -> #REF! | L18: =SUBTOTAL(9,L19:L30) -> #REF! | M18: =SUBTOTAL(9,M19:M30) -> #REF! | N18: =SUM(K18:L18)-M18 -> #REF! | O18: =SUBTOTAL(9,O19:O30) -> #REF! | P18: =SUBTOTAL(9,P19:P30) -> #REF! | S18: =SUBTOTAL(9,S19:S30) -> #REF! | T18: =SUBTOTAL(9,T19:T30) -> #REF! | U18: =SUBTOTAL(9,U19:U30) -> #REF! | V18: =SUBTOTAL(9,V19:V30) -> #REF! | W18: =SUBTOTAL(9,W19:W30) -> #REF! | X18: =SUBTOTAL(9,X19:X30) -> #REF! | Y18: =SUM(V18:W18)-X18 -> #REF! | Z18: =SUBTOTAL(9,Z19:Z30) -> #REF! | AA18: =SUBTOTAL(9,AA19:AA30) -> #REF! | AB18: =SUBTOTAL(9,AB19:AB30) -> #REF! | AC18: =SUM(Z18:AA18)-AB18 -> #REF! | AD18: =SUBTOTAL(9,AD19:AD30) -> #REF! | AE18: =SUBTOTAL(9,AE19:AE30) -> #REF! | AH18: =SUBTOTAL(9,AH19:AH30) -> #REF! | AI18: =SUBTOTAL(9,AI19:AI30) -> #REF! | AJ18: =SUBTOTAL(9,AJ19:AJ30) -> #REF! | AK18: =SUBTOTAL(9,AK19:AK30) -> #REF! | AL18: =SUBTOTAL(9,AL19:AL30) -> #REF! | AM18: =SUBTOTAL(9,AM19:AM30) -> #REF! | AN18: =SUM(AK18:AL18)-AM18 -> #REF! | AO18: =SUBTOTAL(9,AO19:AO30) -> #REF! | AP18: =SUBTOTAL(9,AP19:AP30) -> #REF! | AQ18: =SUBTOTAL(9,AQ19:AQ30) -> #REF! | AR18: =SUM(AO18:AP18)-AQ18 -> #REF! | AS18: =SUBTOTAL(9,AS19:AS30) -> #REF! | AT18: =SUBTOTAL(9,AT19:AT30) -> #REF! | AW18: =SUBTOTAL(9,AW19:AW30) -> #REF! | AX18: =SUBTOTAL(9,AX19:AX30) -> #REF! | AY18: =SUBTOTAL(9,AY19:AY30) -> #REF! | AZ18: =SUBTOTAL(9,AZ19:AZ30) -> #REF! | BA18: =SUBTOTAL(9,BA19:BA30) -> #REF! | BB18: =SUBTOTAL(9,BB19:BB30) -> #REF! | BC18: =SUM(AZ18:BA18)-BB18 -> #REF! | BD18: =SUBTOTAL(9,BD19:BD30) -> #REF! | BE18: =SUBTOTAL(9,BE19:BE30) -> #REF! | BF18: =SUBTOTAL(9,BF19:BF30) -> #REF! | BG18: =SUM(BD18:BE18)-BF18 -> #REF! | BH18: =SUBTOTAL(9,BH19:BH30) -> #REF! | BI18: =SUBTOTAL(9,BI19:BI30) -> #REF! | BL18: =SUBTOTAL(9,BL19:BL30) -> #REF! | BM18: =SUBTOTAL(9,BM19:BM30) -> #REF! | BN18: =SUBTOTAL(9,BN19:BN30) -> #REF! | BO18: =SUBTOTAL(9,BO19:BO30) -> #REF! | BP18: =SUBTOTAL(9,BP19:BP30) -> #REF! | BQ18: =SUBTOTAL(9,BQ19:BQ30) -> #REF! | BR18: =SUM(BO18:BP18)-BQ18 -> #REF! | BS18: =SUBTOTAL(9,BS19:BS30) -> #REF! | BT18: =SUBTOTAL(9,BT19:BT30) -> #REF! | BU18: =SUBTOTAL(9,BU19:BU30) -> #REF! | BV18: =SUM(BS18:BT18)-BU18 -> #REF! | BW18: =SUBTOTAL(9,BW19:BW30) -> #REF! | BX18: =SUBTOTAL(9,BX19:BX30) -> #REF! | CA18: =SUBTOTAL(9,CA19:CA30) -> #REF! | CB18: =SUBTOTAL(9,CB19:CB30) -> #REF! | CC18: =SUBTOTAL(9,CC19:CC30) -> #REF! | CD18: =SUBTOTAL(9,CD19:CD30) -> #REF! | CE18: =SUBTOTAL(9,CE19:CE30) -> #REF! | CF18: =SUBTOTAL(9,CF19:CF30) -> #REF! | CG18: =SUM(CD18:CE18)-CF18 -> #REF! | CH18: =SUBTOTAL(9,CH19:CH30) -> #REF! | CI18: =SUBTOTAL(9,CI19:CI30) -> #REF! | CJ18: =SUBTOTAL(9,CJ19:CJ30) -> #REF! | CK18: =SUM(CH18:CI18)-CJ18 -> #REF! | CL18: =SUBTOTAL(9,CL19:CL30) -> #REF! | CM18: =SUBTOTAL(9,CM19:CM30) -> #REF! | CP18: =SUBTOTAL(9,CP19:CP30) -> #REF! | CQ18: =SUBTOTAL(9,CQ19:CQ30) -> #REF! | CR18: =SUBTOTAL(9,CR19:CR30) -> #REF! | CS18: =SUBTOTAL(9,CS19:CS30) -> #REF! | CT18: =SUBTOTAL(9,CT19:CT30) -> #REF! | CU18: =SUBTOTAL(9,CU19:CU30) -> #REF! | CV18: =SUM(CS18:CT18)-CU18 -> #REF! | CW18: =SUBTOTAL(9,CW19:CW30) -> #REF! | CX18: =SUBTOTAL(9,CX19:CX30) -> #REF! | CY18: =SUBTOTAL(9,CY19:CY30) -> #REF! | CZ18: =SUM(CW18:CX18)-CY18 -> #REF! | DA18: =SUBTOTAL(9,DA19:DA30) -> #REF! | DB18: =SUBTOTAL(9,DB19:DB30) -> #REF! | DE18: =SUBTOTAL(9,DE19:DE30) -> #REF! | DF18: =SUBTOTAL(9,DF19:DF30) -> #REF! | DG18: =SUBTOTAL(9,DG19:DG30) -> #REF! | DH18: =SUBTOTAL(9,DH19:DH30) -> #REF! | DI18: =SUBTOTAL(9,DI19:DI30) -> #REF! | DJ18: =SUBTOTAL(9,DJ19:DJ30) -> #REF! | DK18: =SUM(DH18:DI18)-DJ18 -> #REF! | DL18: =SUBTOTAL(9,DL19:DL30) -> #REF! | DM18: =SUBTOTAL(9,DM19:DM30) -> #REF! | DN18: =SUBTOTAL(9,DN19:DN30) -> #REF! | DO18: =SUM(DL18:DM18)-DN18 -> #REF! | DP18: =SUBTOTAL(9,DP19:DP30) -> #REF! | DQ18: =SUBTOTAL(9,DQ19:DQ30) -> #REF! | DT18: =SUBTOTAL(9,DT19:DT30) -> #REF! | DU18: =SUBTOTAL(9,DU19:DU30) -> #REF! | DV18: =SUBTOTAL(9,DV19:DV30) -> #REF! | DW18: =SUBTOTAL(9,DW19:DW30) -> #REF! | DX18: =SUBTOTAL(9,DX19:DX30) -> #REF! | DY18: =SUBTOTAL(9,DY19:DY30) -> #REF! | DZ18: =SUM(DW18:DX18)-DY18 -> #REF! | EA18: =SUBTOTAL(9,EA19:EA30) -> #REF! | EB18: =SUBTOTAL(9,EB19:EB30) -> #REF! | EC18: =SUBTOTAL(9,EC19:EC30) -> #REF! | ED18: =SUM(EA18:EB18)-EC18 -> #REF! | EE18: =SUBTOTAL(9,EE19:EE30) -> #REF! | EF18: =SUBTOTAL(9,EF19:EF30) -> #REF! | EI18: =SUBTOTAL(9,EI19:EI30) -> #REF! | EJ18: =SUBTOTAL(9,EJ19:EJ30) -> #REF! | EK18: =SUBTOTAL(9,EK19:EK30) -> #REF! | EL18: =SUBTOTAL(9,EL19:EL30) -> #REF! | EM18: =SUBTOTAL(9,EM19:EM30) -> #REF! | EN18: =SUBTOTAL(9,EN19:EN30) -> #REF! | EO18: =SUM(EL18:EM18)-EN18 -> #REF! | EP18: =SUBTOTAL(9,EP19:EP30) -> #REF! | EQ18: =SUBTOTAL(9,EQ19:EQ30) -> #REF! | ER18: =SUBTOTAL(9,ER19:ER30) -> #REF! | ES18: =SUM(EP18:EQ18)-ER18 -> #REF! | ET18: =SUBTOTAL(9,ET19:ET30) -> #REF! | EU18: =SUBTOTAL(9,EU19:EU30) -> #REF! | EX18: =SUBTOTAL(9,EX19:EX30) -> #REF! | EY18: =SUBTOTAL(9,EY19:EY30) -> #REF! | EZ18: =SUBTOTAL(9,EZ19:EZ30) -> #REF! | FA18: =SUBTOTAL(9,FA19:FA30) -> #REF! | FB18: =SUBTOTAL(9,FB19:FB30) -> #REF! | FC18: =SUBTOTAL(9,FC19:FC30) -> #REF! | FD18: =SUM(FA18:FB18)-FC18 -> #REF! | FE18: =SUBTOTAL(9,FE19:FE30) -> #REF! | FF18: =SUBTOTAL(9,FF19:FF30) -> #REF! | FG18: =SUBTOTAL(9,FG19:FG30) -> #REF! | FH18: =SUM(FE18:FF18)-FG18 -> #REF! | FI18: =SUBTOTAL(9,FI19:FI30) -> #REF! | FJ18: =SUBTOTAL(9,FJ19:FJ30) -> #REF! | FM18: =SUBTOTAL(9,FM19:FM30) -> #REF! | FN18: =SUBTOTAL(9,FN19:FN30) -> #REF! | FO18: =SUBTOTAL(9,FO19:FO30) -> #REF! | FP18: =SUBTOTAL(9,FP19:FP30) -> #REF! | FQ18: =SUBTOTAL(9,FQ19:FQ30) -> #REF! | FR18: =SUBTOTAL(9,FR19:FR30) -> #REF! | FS18: =SUM(FP18:FQ18)-FR18 -> #REF! | FT18: =SUBTOTAL(9,FT19:FT30) -> #REF! | FU18: =SUBTOTAL(9,FU19:FU30) -> #REF! | FV18: =SUBTOTAL(9,FV19:FV30) -> #REF! | FW18: =SUM(FT18:FU18)-FV18 -> #REF! | FX18: =SUBTOTAL(9,FX19:FX30) -> #REF! | FY18: =SUBTOTAL(9,FY19:FY30) -> #REF! | GB18: =SUBTOTAL(9,GB19:GB30) -> #REF! | GC18: =SUBTOTAL(9,GC19:GC30) -> #REF! | GD18: =SUBTOTAL(9,GD19:GD30) -> #REF! | GE18: =SUBTOTAL(9,GE19:GE30) -> #REF! | GF18: =SUBTOTAL(9,GF19:GF30) -> #REF! | GG18: =SUBTOTAL(9,GG19:GG30) -> #REF! | GH18: =SUM(GE18:GF18)-GG18 -> #REF! | GI18: =SUBTOTAL(9,GI19:GI30) -> #REF! | GJ18: =SUBTOTAL(9,GJ19:GJ30) -> #REF! | GK18: =SUBTOTAL(9,GK19:GK30) -> #REF! | GL18: =SUM(GI18:GJ18)-GK18 -> #REF! | GM18: =SUBTOTAL(9,GM19:GM30) -> #REF! | GN18: =SUBTOTAL(9,GN19:GN30) -> #REF! | GQ18: =SUBTOTAL(9,GQ19:GQ30) -> #REF! | GR18: =SUBTOTAL(9,GR19:GR30) -> #REF! | GS18: =SUBTOTAL(9,GS19:GS30) -> #REF! | GT18: =SUBTOTAL(9,GT19:GT30) -> #REF! | GU18: =SUBTOTAL(9,GU19:GU30) -> #REF! | GV18: =SUBTOTAL(9,GV19:GV30) -> #REF! | GW18: =SUM(GT18:GU18)-GV18 -> #REF! | GX18: =SUBTOTAL(9,GX19:GX30) -> #REF! | GY18: =SUBTOTAL(9,GY19:GY30) -> #REF! | GZ18: =SUBTOTAL(9,GZ19:GZ30) -> #REF! | HA18: =SUM(GX18:GY18)-GZ18 -> #REF! | HB18: =SUBTOTAL(9,HB19:HB30) -> #REF! | HC18: =SUBTOTAL(9,HC19:HC30) -> #REF! | HF18: =SUBTOTAL(9,HF19:HF30) -> #REF! | HG18: =SUBTOTAL(9,HG19:HG30) -> #REF! | HH18: =SUBTOTAL(9,HH19:HH30) -> #REF! | HI18: =SUBTOTAL(9,HI19:HI30) -> #REF! | HJ18: =SUBTOTAL(9,HJ19:HJ30) -> #REF! | HK18: =SUBTOTAL(9,HK19:HK30) -> #REF! | HL18: =SUM(HI18:HJ18)-HK18 -> #REF! | HM18: =SUBTOTAL(9,HM19:HM30) -> #REF! | HN18: =SUBTOTAL(9,HN19:HN30) -> #REF! | HO18: =SUBTOTAL(9,HO19:HO30) -> #REF! | HP18: =SUM(HM18:HN18)-HO18 -> #REF! | HQ18: =SUBTOTAL(9,HQ19:HQ30) -> #REF! | HR18: =SUBTOTAL(9,HR19:HR30) -> #REF! | HU18: =SUBTOTAL(9,HU19:HU30) -> #REF! | HV18: =SUBTOTAL(9,HV19:HV30) -> #REF! | HW18: =SUBTOTAL(9,HW19:HW30) -> #REF! | HX18: =SUBTOTAL(9,HX19:HX30) -> #REF! | HY18: =SUBTOTAL(9,HY19:HY30) -> #REF! | HZ18: =SUBTOTAL(9,HZ19:HZ30) -> #REF! | IA18: =SUM(HX18:HY18)-HZ18 -> #REF! | IB18: =SUBTOTAL(9,IB19:IB30) -> #REF! | IC18: =SUBTOTAL(9,IC19:IC30) -> #REF! | ID18: =SUBTOTAL(9,ID19:ID30) -> #REF! | IE18: =SUM(IB18:IC18)-ID18 -> #REF! | IF18: =SUBTOTAL(9,IF19:IF30) -> #REF! | IG18: =SUBTOTAL(9,IG19:IG30) -> #REF! | IJ18: =SUBTOTAL(9,IJ19:IJ30) -> #REF! | IK18: =SUBTOTAL(9,IK19:IK30) -> #REF! | IL18: =SUBTOTAL(9,IL19:IL30) -> #REF! | IM18: =SUBTOTAL(9,IM19:IM30) -> #REF! | IN18: =SUBTOTAL(9,IN19:IN30) -> #REF! | IO18: =SUBTOTAL(9,IO19:IO30) -> #REF! | IP18: =SUM(IM18:IN18)-IO18 -> #REF! | IQ18: =SUBTOTAL(9,IQ19:IQ30) -> #REF! | IR18: =SUBTOTAL(9,IR19:IR30) -> #REF! | IS18: =SUBTOTAL(9,IS19:IS30) -> #REF! | IT18: =SUM(IQ18:IR18)-IS18 -> #REF! | IU18: =SUBTOTAL(9,IU19:IU30) -> #REF! | IV18: =SUBTOTAL(9,IV19:IV30) -> #REF! | IY18: =SUBTOTAL(9,IY19:IY30) -> #REF! | IZ18: =SUBTOTAL(9,IZ19:IZ30) -> #REF! | JA18: =SUBTOTAL(9,JA19:JA30) -> #REF! | JB18: =SUBTOTAL(9,JB19:JB30) -> #REF! | JC18: =SUBTOTAL(9,JC19:JC30) -> #REF! | JD18: =SUBTOTAL(9,JD19:JD30) -> #REF! | JE18: =SUM(JB18:JC18)-JD18 -> #REF! | JF18: =SUBTOTAL(9,JF19:JF30) -> #REF! | JG18: =SUBTOTAL(9,JG19:JG30) -> #REF! | JH18: =SUBTOTAL(9,JH19:JH30) -> #REF! | JI18: =SUM(JF18:JG18)-JH18 -> #REF! | JJ18: =SUBTOTAL(9,JJ19:JJ30) -> #REF! | JK18: =SUBTOTAL(9,JK19:JK30) -> #REF! | JN18: =SUBTOTAL(9,JN19:JN30) -> #REF! | JO18: =SUBTOTAL(9,JO19:JO30) -> #REF! | JP18: =SUBTOTAL(9,JP19:JP30) -> #REF! | JQ18: =SUBTOTAL(9,JQ19:JQ30) -> #REF! | JR18: =SUBTOTAL(9,JR19:JR30) -> #REF! | JS18: =SUBTOTAL(9,JS19:JS30) -> #REF! | JT18: =SUM(JQ18:JR18)-JS18 -> #REF! | JU18: =SUBTOTAL(9,JU19:JU30) -> #REF! | JV18: =SUBTOTAL(9,JV19:JV30) -> #REF! | JW18: =SUBTOTAL(9,JW19:JW30) -> #REF! | JX18: =SUM(JU18:JV18)-JW18 -> #REF! | JY18: =SUBTOTAL(9,JY19:JY30) -> #REF! | JZ18: =SUBTOTAL(9,JZ19:JZ30) -> #REF! | KC18: =SUBTOTAL(9,KC19:KC30) -> #REF! | KD18: =SUBTOTAL(9,KD19:KD30) -> #REF! | KE18: =SUBTOTAL(9,KE19:KE30) -> #REF! | KF18: =SUBTOTAL(9,KF19:KF30) -> #REF! | KG18: =SUBTOTAL(9,KG19:KG30) -> #REF! | KH18: =SUBTOTAL(9,KH19:KH30) -> #REF! | KI18: =SUM(KF18:KG18)-KH18 -> #REF! | KJ18: =SUBTOTAL(9,KJ19:KJ30) -> #REF! | KK18: =SUBTOTAL(9,KK19:KK30) -> #REF! | KL18: =SUBTOTAL(9,KL19:KL30) -> #REF! | KM18: =SUM(KJ18:KK18)-KL18 -> #REF! | KN18: =SUBTOTAL(9,KN19:KN30) -> #REF! | KO18: =SUBTOTAL(9,KO19:KO30) -> #REF! | KR18: =SUBTOTAL(9,KR19:KR30) -> #REF! | KS18: =SUBTOTAL(9,KS19:KS30) -> #REF! | KT18: =SUBTOTAL(9,KT19:KT30) -> #REF! | KU18: =SUBTOTAL(9,KU19:KU30) -> #REF! | KV18: =SUBTOTAL(9,KV19:KV30) -> #REF! | KW18: =SUBTOTAL(9,KW19:KW30) -> #REF! | KX18: =SUM(KU18:KV18)-KW18 -> #REF! | KY18: =SUBTOTAL(9,KY19:KY30) -> #REF! | KZ18: =SUBTOTAL(9,KZ19:KZ30) -> #REF! | LA18: =SUBTOTAL(9,LA19:LA30) -> #REF! | LB18: =SUM(KY18:KZ18)-LA18 -> #REF! | LC18: =SUBTOTAL(9,LC19:LC30) -> #REF! | LD18: =SUBTOTAL(9,LD19:LD30) -> #REF! | LG18: =SUBTOTAL(9,LG19:LG30) -> #REF! | LH18: =SUBTOTAL(9,LH19:LH30) -> #REF! | LI18: =SUBTOTAL(9,LI19:LI30) -> #REF! | LJ18: =SUBTOTAL(9,LJ19:LJ30) -> #REF! | LK18: =SUBTOTAL(9,LK19:LK30) -> #REF! | LL18: =SUBTOTAL(9,LL19:LL30) -> #REF! | LM18: =SUM(LJ18:LK18)-LL18 -> #REF! | LN18: =SUBTOTAL(9,LN19:LN30) -> #REF! | LO18: =SUBTOTAL(9,LO19:LO30) -> #REF! | LP18: =SUBTOTAL(9,LP19:LP30) -> #REF! | LQ18: =SUM(LN18:LO18)-LP18 -> #REF! | LR18: =SUBTOTAL(9,LR19:LR30) -> #REF! | LS18: =SUBTOTAL(9,LS19:LS30) -> #REF! | LV18: =SUBTOTAL(9,LV19:LV30) -> #REF! | LW18: =SUBTOTAL(9,LW19:LW30) -> #REF! | LX18: =SUBTOTAL(9,LX19:LX30) -> #REF! | LY18: =SUBTOTAL(9,LY19:LY30) -> #REF! | LZ18: =SUBTOTAL(9,LZ19:LZ30) -> #REF! | MA18: =SUBTOTAL(9,MA19:MA30) -> #REF! | MB18: =SUM(LY18:LZ18)-MA18 -> #REF! | MC18: =SUBTOTAL(9,MC19:MC30) -> #REF! | MD18: =SUBTOTAL(9,MD19:MD30) -> #REF! | ME18: =SUBTOTAL(9,ME19:ME30) -> #REF! | MF18: =SUM(MC18:MD18)-ME18 -> #REF! | MG18: =SUBTOTAL(9,MG19:MG30) -> #REF! | MH18: =SUBTOTAL(9,MH19:MH30) -> #REF! | MK18: =SUBTOTAL(9,MK19:MK30) -> #REF! | ML18: =SUBTOTAL(9,ML19:ML30) -> #REF! | MM18: =SUBTOTAL(9,MM19:MM30) -> #REF! | MN18: =SUBTOTAL(9,MN19:MN30) -> #REF! | MO18: =SUBTOTAL(9,MO19:MO30) -> #REF! | MP18: =SUBTOTAL(9,MP19:MP30) -> #REF! | MQ18: =SUM(MN18:MO18)-MP18 -> #REF! | MR18: =SUBTOTAL(9,MR19:MR30) -> #REF! | MS18: =SUBTOTAL(9,MS19:MS30) -> #REF! | MT18: =SUBTOTAL(9,MT19:MT30) -> #REF! | MU18: =SUM(MR18:MS18)-MT18 -> #REF! | MV18: =SUBTOTAL(9,MV19:MV30) -> #REF! | MW18: =SUBTOTAL(9,MW19:MW30) -> #REF! | MZ18: =SUBTOTAL(9,MZ19:MZ30) -> #REF! | NA18: =SUBTOTAL(9,NA19:NA30) -> #REF! | NB18: =SUBTOTAL(9,NB19:NB30) -> #REF! | NC18: =SUBTOTAL(9,NC19:NC30) -> #REF! | ND18: =SUBTOTAL(9,ND19:ND30) -> #REF! | NE18: =SUBTOTAL(9,NE19:NE30) -> #REF! | NF18: =SUM(NC18:ND18)-NE18 -> #REF! | NG18: =SUBTOTAL(9,NG19:NG30) -> #REF! | NH18: =SUBTOTAL(9,NH19:NH30) -> #REF! | NI18: =SUBTOTAL(9,NI19:NI30) -> #REF! | NJ18: =SUM(NG18:NH18)-NI18 -> #REF! | NK18: =SUBTOTAL(9,NK19:NK30) -> #REF! | NL18: =SUBTOTAL(9,NL19:NL30) -> #REF! | NO18: =SUBTOTAL(9,NO19:NO30) -> #REF! | NP18: =SUBTOTAL(9,NP19:NP30) -> #REF! | NQ18: =SUBTOTAL(9,NQ19:NQ30) -> #REF! | NR18: =SUBTOTAL(9,NR19:NR30) -> #REF! | NS18: =SUBTOTAL(9,NS19:NS30) -> #REF! | NT18: =SUBTOTAL(9,NT19:NT30) -> #REF! | NU18: =SUM(NR18:NS18)-NT18 -> #REF! | NV18: =SUBTOTAL(9,NV19:NV30) -> #REF! | NW18: =SUBTOTAL(9,NW19:NW30) -> #REF! | NX18: =SUBTOTAL(9,NX19:NX30) -> #REF! | NY18: =SUM(NV18:NW18)-NX18 -> #REF! | NZ18: =SUBTOTAL(9,NZ19:NZ30) -> #REF! | OA18: =SUBTOTAL(9,OA19:OA30) -> #REF! | OD18: =SUBTOTAL(9,OD19:OD30) -> #REF! | OE18: =SUBTOTAL(9,OE19:OE30) -> #REF! | OF18: =SUBTOTAL(9,OF19:OF30) -> #REF! | OG18: =SUBTOTAL(9,OG19:OG30) -> #REF! | OH18: =SUBTOTAL(9,OH19:OH30) -> #REF! | OI18: =SUBTOTAL(9,OI19:OI30) -> #REF! | OJ18: =SUM(OG18:OH18)-OI18 -> #REF! | OK18: =SUBTOTAL(9,OK19:OK30) -> #REF! | OL18: =SUBTOTAL(9,OL19:OL30) -> #REF! | OM18: =SUBTOTAL(9,OM19:OM30) -> #REF! | ON18: =SUM(OK18:OL18)-OM18 -> #REF! | OO18: =SUBTOTAL(9,OO19:OO30) -> #REF! | OP18: =SUBTOTAL(9,OP19:OP30) -> #REF! | OS18: =SUBTOTAL(9,OS19:OS30) -> #REF! | OT18: =SUBTOTAL(9,OT19:OT30) -> #REF! | OU18: =SUBTOTAL(9,OU19:OU30) -> #REF! | OV18: =SUBTOTAL(9,OV19:OV30) -> #REF! | OW18: =SUBTOTAL(9,OW19:OW30) -> #REF! | OX18: =SUBTOTAL(9,OX19:OX30) -> #REF! | OY18: =SUM(OV18:OW18)-OX18 -> #REF! | OZ18: =SUBTOTAL(9,OZ19:OZ30) -> #REF! | PA18: =SUBTOTAL(9,PA19:PA30) -> #REF! | PB18: =SUBTOTAL(9,PB19:PB30) -> #REF! | PC18: =SUM(OZ18:PA18)-PB18 -> #REF! | PD18: =SUBTOTAL(9,PD19:PD30) -> #REF! | PE18: =SUBTOTAL(9,PE19:PE30) -> #REF! | PH18: =SUBTOTAL(9,PH19:PH30) -> #REF! | PI18: =SUBTOTAL(9,PI19:PI30) -> #REF! | PJ18: =SUBTOTAL(9,PJ19:PJ30) -> #REF! | PK18: =SUBTOTAL(9,PK19:PK30) -> #REF! | PL18: =SUBTOTAL(9,PL19:PL30) -> #REF! | PM18: =SUBTOTAL(9,PM19:PM30) -> #REF! | PN18: =SUM(PK18:PL18)-PM18 -> #REF! | PO18: =SUBTOTAL(9,PO19:PO30) -> #REF! | PP18: =SUBTOTAL(9,PP19:PP30) -> #REF! | PQ18: =SUBTOTAL(9,PQ19:PQ30) -> #REF! | PR18: =SUM(PO18:PP18)-PQ18 -> #REF! | PS18: =SUBTOTAL(9,PS19:PS30) -> #REF! | PT18: =SUBTOTAL(9,PT19:PT30) -> #REF! | PW18: =SUBTOTAL(9,PW19:PW30) -> #REF! | PX18: =SUBTOTAL(9,PX19:PX30) -> #REF! | PY18: =SUBTOTAL(9,PY19:PY30) -> #REF! | PZ18: =SUBTOTAL(9,PZ19:PZ30) -> #REF! | QA18: =SUBTOTAL(9,QA19:QA30) -> #REF! | QB18: =SUBTOTAL(9,QB19:QB30) -> #REF! | QC18: =SUM(PZ18:QA18)-QB18 -> #REF! | QD18: =SUBTOTAL(9,QD19:QD30) -> #REF! | QE18: =SUBTOTAL(9,QE19:QE30) -> #REF! | QF18: =SUBTOTAL(9,QF19:QF30) -> #REF! | QG18: =SUM(QD18:QE18)-QF18 -> #REF! | QH18: =SUBTOTAL(9,QH19:QH30) -> #REF! | QI18: =SUBTOTAL(9,QI19:QI30) -> #REF! | QL18: =SUBTOTAL(9,QL19:QL30) -> #REF! | QM18: =SUBTOTAL(9,QM19:QM30) -> #REF! | QN18: =SUBTOTAL(9,QN19:QN30) -> #REF! | QO18: =SUBTOTAL(9,QO19:QO30) -> #REF! | QP18: =SUBTOTAL(9,QP19:QP30) -> #REF! | QQ18: =SUBTOTAL(9,QQ19:QQ30) -> #REF! | QR18: =SUM(QO18:QP18)-QQ18 -> #REF! | QS18: =SUBTOTAL(9,QS19:QS30) -> #REF! | QT18: =SUBTOTAL(9,QT19:QT30) -> #REF! | QU18: =SUBTOTAL(9,QU19:QU30) -> #REF! | QV18: =SUM(QS18:QT18)-QU18 -> #REF! | QW18: =SUBTOTAL(9,QW19:QW30) -> #REF! | QX18: =SUBTOTAL(9,QX19:QX30) -> #REF! | RA18: =SUBTOTAL(9,RA19:RA30) -> #REF! | RB18: =SUBTOTAL(9,RB19:RB30) -> #REF! | RC18: =SUBTOTAL(9,RC19:RC30) -> #REF! | RD18: =SUBTOTAL(9,RD19:RD30) -> #REF! | RE18: =SUBTOTAL(9,RE19:RE30) -> #REF! | RF18: =SUBTOTAL(9,RF19:RF30) -> #REF! | RG18: =SUM(RD18:RE18)-RF18 -> #REF! | RH18: =SUBTOTAL(9,RH19:RH30) -> #REF! | RI18: =SUBTOTAL(9,RI19:RI30) -> #REF! | RJ18: =SUBTOTAL(9,RJ19:RJ30) -> #REF! | RK18: =SUM(RH18:RI18)-RJ18 -> #REF! | RL18: =SUBTOTAL(9,RL19:RL30) -> #REF! | RM18: =SUBTOTAL(9,RM19:RM30) -> #REF! | RP18: =SUBTOTAL(9,RP19:RP30) -> #REF! | RQ18: =SUBTOTAL(9,RQ19:RQ30) -> #REF! | RR18: =SUBTOTAL(9,RR19:RR30) -> #REF! | RS18: =SUBTOTAL(9,RS19:RS30) -> #REF! | RT18: =SUBTOTAL(9,RT19:RT30) -> #REF! | RU18: =SUBTOTAL(9,RU19:RU30) -> #REF! | RV18: =SUM(RS18:RT18)-RU18 -> #REF! | RW18: =SUBTOTAL(9,RW19:RW30) -> #REF! | RX18: =SUBTOTAL(9,RX19:RX30) -> #REF! | RY18: =SUBTOTAL(9,RY19:RY30) -> #REF! | RZ18: =SUM(RW18:RX18)-RY18 -> #REF! | SA18: =SUBTOTAL(9,SA19:SA30) -> #REF! | SB18: =SUBTOTAL(9,SB19:SB30) -> #REF! | SE18: =SUBTOTAL(9,SE19:SE30) -> #REF! | SF18: =SUBTOTAL(9,SF19:SF30) -> #REF! | SG18: =SUBTOTAL(9,SG19:SG30) -> #REF! | SH18: =SUBTOTAL(9,SH19:SH30) -> #REF! | SI18: =SUBTOTAL(9,SI19:SI30) -> #REF! | SJ18: =SUBTOTAL(9,SJ19:SJ30) -> #REF! | SK18: =SUM(SH18:SI18)-SJ18 -> #REF! | SL18: =SUBTOTAL(9,SL19:SL30) -> #REF! | SM18: =SUBTOTAL(9,SM19:SM30) -> #REF! | SN18: =SUBTOTAL(9,SN19:SN30) -> #REF! | SO18: =SUM(SL18:SM18)-SN18 -> #REF! | SP18: =SUBTOTAL(9,SP19:SP30) -> #REF! | SQ18: =SUBTOTAL(9,SQ19:SQ30) -> #REF! | ST18: =SUBTOTAL(9,ST19:ST30) -> #REF! | SU18: =SUBTOTAL(9,SU19:SU30) -> #REF! | SV18: =SUBTOTAL(9,SV19:SV30) -> #REF! | SW18: =SUBTOTAL(9,SW19:SW30) -> #REF! | SX18: =SUBTOTAL(9,SX19:SX30) -> #REF! | SY18: =SUBTOTAL(9,SY19:SY30) -> #REF! | SZ18: =SUM(SW18:SX18)-SY18 -> #REF! | TA18: =SUBTOTAL(9,TA19:TA30) -> #REF! | TB18: =SUBTOTAL(9,TB19:TB30) -> #REF! | TC18: =SUBTOTAL(9,TC19:TC30) -> #REF! | TD18: =SUM(TA18:TB18)-TC18 -> #REF! | TE18: =SUBTOTAL(9,TE19:TE30) -> #REF! | TF18: =SUBTOTAL(9,TF19:TF30) -> #REF! | TI18: =SUBTOTAL(9,TI19:TI30) -> #REF! | TJ18: =SUBTOTAL(9,TJ19:TJ30) -> #REF! | TK18: =SUBTOTAL(9,TK19:TK30) -> #REF! | TL18: =SUBTOTAL(9,TL19:TL30) -> #REF! | TM18: =SUBTOTAL(9,TM19:TM30) -> #REF! | TN18: =SUBTOTAL(9,TN19:TN30) -> #REF! | TO18: =SUM(TL18:TM18)-TN18 -> #REF! | TP18: =SUBTOTAL(9,TP19:TP30) -> #REF! | TQ18: =SUBTOTAL(9,TQ19:TQ30) -> #REF! | TR18: =SUBTOTAL(9,TR19:TR30) -> #REF! | TS18: =SUM(TP18:TQ18)-TR18 -> #REF! | TT18: =SUBTOTAL(9,TT19:TT30) -> #REF! | TU18: =SUBTOTAL(9,TU19:TU30) -> #REF! | TX18: =SUBTOTAL(9,TX19:TX30) -> #REF! | TY18: =SUBTOTAL(9,TY19:TY30) -> #REF! | TZ18: =SUBTOTAL(9,TZ19:TZ30) -> #REF! | UA18: =SUBTOTAL(9,UA19:UA30) -> #REF! | UB18: =SUBTOTAL(9,UB19:UB30) -> #REF! | UC18: =SUBTOTAL(9,UC19:UC30) -> #REF! | UD18: =SUM(UA18:UB18)-UC18 -> #REF! | UE18: =SUBTOTAL(9,UE19:UE30) -> #REF! | UF18: =SUBTOTAL(9,UF19:UF30) -> #REF! | UG18: =SUBTOTAL(9,UG19:UG30) -> #REF! | UH18: =SUM(UE18:UF18)-UG18 -> #REF! | UI18: =SUBTOTAL(9,UI19:UI30) -> #REF! | UJ18: =SUBTOTAL(9,UJ19:UJ30) -> #REF! | UM18: =SUBTOTAL(9,UM19:UM30) -> #REF! | UN18: =SUBTOTAL(9,UN19:UN30) -> #REF! | UO18: =SUBTOTAL(9,UO19:UO30) -> #REF! | UP18: =SUBTOTAL(9,UP19:UP30) -> #REF! | UQ18: =SUBTOTAL(9,UQ19:UQ30) -> #REF! | UR18: =SUBTOTAL(9,UR19:UR30) -> #REF! | US18: =SUM(UP18:UQ18)-UR18 -> #REF! | UT18: =SUBTOTAL(9,UT19:UT30) -> #REF! | UU18: =SUBTOTAL(9,UU19:UU30) -> #REF! | UV18: =SUBTOTAL(9,UV19:UV30) -> #REF! | UW18: =SUM(UT18:UU18)-UV18 -> #REF! | UX18: =SUBTOTAL(9,UX19:UX30) -> #REF! | UY18: =SUBTOTAL(9,UY19:UY30) -> #REF! | VB18: =SUBTOTAL(9,VB19:VB30) -> #REF! | VC18: =SUBTOTAL(9,VC19:VC30) -> #REF! | VD18: =SUBTOTAL(9,VD19:VD30) -> #REF! | VE18: =SUBTOTAL(9,VE19:VE30) -> #REF! | VF18: =SUBTOTAL(9,VF19:VF30) -> #REF! | VG18: =SUBTOTAL(9,VG19:VG30) -> #REF! | VH18: =SUM(VE18:VF18)-VG18 -> #REF! | VI18: =SUBTOTAL(9,VI19:VI30) -> #REF! | VJ18: =SUBTOTAL(9,VJ19:VJ30) -> #REF! | VK18: =SUBTOTAL(9,VK19:VK30) -> #REF! | VL18: =SUM(VI18:VJ18)-VK18 -> #REF! | VM18: =SUBTOTAL(9,VM19:VM30) -> #REF! | VN18: =SUBTOTAL(9,VN19:VN30) -> #REF! | VQ18: =SUBTOTAL(9,VQ19:VQ30) -> #REF! | VR18: =SUBTOTAL(9,VR19:VR30) -> #REF! | VS18: =SUBTOTAL(9,VS19:VS30) -> #REF! | VT18: =SUBTOTAL(9,VT19:VT30) -> #REF! | VU18: =SUBTOTAL(9,VU19:VU30) -> #REF! | VV18: =SUBTOTAL(9,VV19:VV30) -> #REF! | VW18: =SUM(VT18:VU18)-VV18 -> #REF! | VX18: =SUBTOTAL(9,VX19:VX30) -> #REF! | VY18: =SUBTOTAL(9,VY19:VY30) -> #REF! | VZ18: =SUBTOTAL(9,VZ19:VZ30) -> #REF! | WA18: =SUM(VX18:VY18)-VZ18 -> #REF! | WB18: =SUBTOTAL(9,WB19:WB30) -> #REF! | WC18: =SUBTOTAL(9,WC19:WC30) -> #REF!
